<?xml version="1.0" ?>
<!-- Generated using onshape-to-robot -->
<!-- Onshape https://cad.onshape.com/documents/fb0923073e8e7a4d8f326f1d/w/e1fdacee02992b8a3e4bd626/e/49e3fdf89d48331afae0308a -->
<mujoco model="mjcf">
  <compiler angle="radian" meshdir="assets" autolimits="true"/>
  <default>
    <default class="mjcf">
      <joint frictionloss="0.1" armature="0.005"/>
      <position kp="50" dampratio="1"/>
      <default class="visual">
        <geom type="mesh" contype="0" conaffinity="0" group="2"/>
      </default>
      <default class="collision">
        <geom group="3"/>
      </default>
    </default>
  </default>
  <!-- Additional joints_properties.xml -->
  <default>
    <default class="perfect_actuator">
      <geom contype="0" conaffinity="0"/>
      <joint damping="0.095" frictionloss="0.001" armature="0.001" range="-1.5707963267948966 1.5707963267948966"/>
      <position kp="10.0" kv="0.0" forcerange="-10.0 10.0"/>
      <default class="chosen_actuator"/>
    </default>
    <default class="xc330m288t">
      <!-- probably wrong, would need to re-identify -->
      <geom contype="0" conaffinity="0"/>
      <joint damping="0.095" frictionloss="0.058" armature="0.0018"/>
      <position kp="2.54" kv="0.0" forcerange="-0.8 0.8"/>
    </default>
    <default class="sts3215_345">
      <!-- Standard sts3215 with 1/345 gear ratio -->
      <!-- Confident that this is realistic (mini duck walks with these values) -->
      <geom contype="0" conaffinity="0"/>
      <joint damping="0.56" frictionloss="0.068" armature="0.027"/>
      <position kp="17.11" kv="0.0" forcerange="-3.23 3.23"/>
    </default>
    <default class="sts3215_147">
      <!-- sts3215 with 1/147 gear ratio -->
      <!-- (Estimation based on the gear ratio difference) -->
      <geom contype="0" conaffinity="0"/>
      <joint damping="0.1" frictionloss="0.028" armature="0.011"/>
      <position kp="17.11" kv="0.0" forcerange="-1.35 1.35"/>
    </default>
  </default>
  <!-- Additional additional.xml -->
  <contact>
    <!-- <exclude name="exclude0" body1="torso" body2="sts32155"/> -->
  </contact>
  <default>
    <equality solref="0.002 1" solimp="0.99 0.999 0.0005 0.5 2"/>
  </default>
  <worldbody>
    <!-- Link r_wrist_interface -->
    <body name="r_wrist_interface" pos="0 0 0" quat="1 0 0 0" childclass="mjcf">
      <inertial pos="-0.0129275 -0.0025481 0.0570037" mass="0.160126" fullinertia="0.000178145 0.000104513 0.000125587 -1.4624e-05 2.97375e-05 9.50115e-06"/>
      <!-- Part sts3032 -->
      <geom type="mesh" class="visual" pos="-0.00800001 0.02905 0.070198" quat="0.5 0.5 0.5 0.5" mesh="sts3032" material="sts3032_material"/>
      <!-- Part r_hand_plate -->
      <geom type="mesh" class="visual" pos="-0.0115 0.023 0.1022" quat="0.5 0.5 -0.5 -0.5" mesh="r_hand_plate" material="r_hand_plate_material"/>
      <!-- Part sts3032_2 -->
      <geom type="mesh" class="visual" pos="-0.00406342 0.0177398 0.0332" quat="0.819152 7.32351e-15 9.9365e-15 -0.573576" mesh="sts3032" material="sts3032_material"/>
      <!-- Part finger_frame -->
      <geom type="mesh" class="visual" pos="-0.0115 -0.0098 0.0961543" quat="0.48674 0.512917 -0.48674 -0.512917" mesh="finger_frame" material="finger_frame_material"/>
      <!-- Part finger_frame_2 -->
      <geom type="mesh" class="visual" pos="-0.0115 -0.042 0.0851417" quat="0.468543 0.529592 -0.468543 -0.529592" mesh="finger_frame" material="finger_frame_material"/>
      <!-- Part bushing_0608_04 -->
      <geom type="mesh" class="visual" pos="-0.015 -0.0098 0.0961543" quat="0.512917 -0.48674 0.512917 -0.48674" mesh="bushing_0608_04" material="bushing_0608_04_material"/>
      <!-- Part bushing_0608_04_2 -->
      <geom type="mesh" class="visual" pos="-0.015 0.023 0.1022" quat="0.5 -0.5 0.5 -0.5" mesh="bushing_0608_04" material="bushing_0608_04_material"/>
      <!-- Part bushing_0608_04_3 -->
      <geom type="mesh" class="visual" pos="-0.015 -0.042 0.0851417" quat="0.529592 -0.468543 0.529592 -0.468543" mesh="bushing_0608_04" material="bushing_0608_04_material"/>
      <!-- Part bushing_0608_04_4 -->
      <geom type="mesh" class="visual" pos="-0.025 -0.0098 0.0961543" quat="0.48674 0.512917 -0.48674 -0.512917" mesh="bushing_0608_04" material="bushing_0608_04_material"/>
      <!-- Part finger_frame_3 -->
      <geom type="mesh" class="visual" pos="0.0280778 0.023 0.0297" quat="4.13309e-16 0.573576 0.819152 6.85594e-16" mesh="finger_frame" material="finger_frame_material"/>
      <!-- Part sts3032_3 -->
      <geom type="mesh" class="visual" pos="-0.00800001 -0.0141669 0.0638795" quat="0.48674 0.512917 0.48674 0.512917" mesh="sts3032" material="sts3032_material"/>
      <!-- Part sts3032_4 -->
      <geom type="mesh" class="visual" pos="-0.00800001 0.01695 0.070198" quat="0.5 0.5 0.5 0.5" mesh="sts3032" material="sts3032_material"/>
      <!-- Part finger_frame_4 -->
      <geom type="mesh" class="visual" pos="-0.0115 0.023 0.1022" quat="0.5 0.5 -0.5 -0.5" mesh="finger_frame" material="finger_frame_material"/>
      <!-- Part sts3032_5 -->
      <geom type="mesh" class="visual" pos="-0.00800001 -0.00208344 0.0645128" quat="0.48674 0.512917 0.48674 0.512917" mesh="sts3032" material="sts3032_material"/>
      <!-- Part sts3032_6 -->
      <geom type="mesh" class="visual" pos="-0.00800001 -0.0441048 0.052641" quat="0.468543 0.529592 0.468543 0.529592" mesh="sts3032" material="sts3032_material"/>
      <!-- Part bushing_0608_04_5 -->
      <geom type="mesh" class="visual" pos="0.0280778 0.023 0.0262" quat="0.573576 -3.73805e-16 -8.32667e-16 0.819152" mesh="bushing_0608_04" material="bushing_0608_04_material"/>
      <!-- Part sts3032_7 -->
      <geom type="mesh" class="visual" pos="-0.00800001 -0.032095 0.0541156" quat="0.468543 0.529592 0.468543 0.529592" mesh="sts3032" material="sts3032_material"/>
      <!-- Part r_wrist_interface -->
      <geom type="mesh" class="visual" pos="-0.0115 0.023 0.1022" quat="0.5 0.5 -0.5 -0.5" mesh="r_wrist_interface" material="r_wrist_interface_material"/>
      <!-- Part sts3032_8 -->
      <geom type="mesh" class="visual" pos="7.5027e-05 0.00636953 0.0332" quat="0.819152 6.79914e-16 -3.33067e-16 -0.573576" mesh="sts3032" material="sts3032_material"/>
      <!-- Part bushing_0608_04_6 -->
      <geom type="mesh" class="visual" pos="-0.025 0.023 0.1022" quat="0.5 0.5 -0.5 -0.5" mesh="bushing_0608_04" material="bushing_0608_04_material"/>
      <!-- Part bushing_0608_04_7 -->
      <geom type="mesh" class="visual" pos="-0.025 -0.042 0.0851417" quat="0.468543 0.529592 -0.468543 -0.529592" mesh="bushing_0608_04" material="bushing_0608_04_material"/>
      <!-- Part bushing_0608_04_8 -->
      <geom type="mesh" class="visual" pos="0.0280778 0.023 0.0162" quat="2.74447e-16 0.573576 0.819152 4.56774e-16" mesh="bushing_0608_04" material="bushing_0608_04_material"/>
      <!-- Frame closing_1 (1)_2 -->
      <site group="3" name="closing_1 (1)_2" pos="-0.015 0.023 0.1022" quat="0.5 0.5 -0.5 -0.5"/>
      <!-- Frame closing_1 (1)_2_z -->
      <site group="3" name="closing_1 (1)_2_z" pos="-0.115 0.023 0.1022" quat="0.5 0.5 -0.5 -0.5"/>
      <!-- Frame closing_1 (2)_2 -->
      <site group="3" name="closing_1 (2)_2" pos="-0.015 -0.0098 0.0961543" quat="0.48674 0.512917 -0.48674 -0.512917"/>
      <!-- Frame closing_1 (2)_2_z -->
      <site group="3" name="closing_1 (2)_2_z" pos="-0.115 -0.0098 0.0961543" quat="0.48674 0.512917 -0.48674 -0.512917"/>
      <!-- Frame closing_1 (3)_2 -->
      <site group="3" name="closing_1 (3)_2" pos="-0.015 -0.042 0.0851417" quat="0.468543 0.529592 -0.468543 -0.529592"/>
      <!-- Frame closing_1 (3)_2_z -->
      <site group="3" name="closing_1 (3)_2_z" pos="-0.115 -0.042 0.0851417" quat="0.468543 0.529592 -0.468543 -0.529592"/>
      <!-- Frame closing_1 (4)_2 -->
      <site group="3" name="closing_1 (4)_2" pos="0.0280778 0.023 0.0262" quat="4.19588e-16 0.573576 0.819152 6.96695e-16"/>
      <!-- Frame closing_1 (4)_2_z -->
      <site group="3" name="closing_1 (4)_2_z" pos="0.0280778 0.023 -0.0738" quat="4.19588e-16 0.573576 0.819152 6.96695e-16"/>
      <!-- Link side_arm -->
      <body name="side_arm" pos="-0.0046 0.02905 0.070198" quat="0.5 -0.5 -0.5 0.5">
        <!-- Joint from r_wrist_interface to side_arm -->
        <joint axis="0 0 1" name="finger1_motor1" type="hinge" range="-1.3962634015956095 1.3962634015953177"/>
        <inertial pos="0.006 -2.85616e-17 -0.00345938" mass="0.000410988" fullinertia="4.63584e-09 4.63584e-09 1e-09 -3.10786e-23 -1.75943e-22 1.49074e-24"/>
        <!-- Part rotule_ball -->
        <geom type="mesh" class="visual" pos="0.006 -1.38778e-17 -0.0038" quat="0.707107 -7.12267e-15 6.32827e-15 -0.707107" mesh="rotule_ball" material="rotule_ball_material"/>
        <!-- Part ph_pan_head_screw_m2x0_40_x_10__2803432263e518bbd16bccbbef8784ed -->
        <geom type="mesh" class="visual" pos="0.006 -4.16334e-17 -0.0083" quat="5.27466e-16 1 -1.67921e-15 -9.54551e-15" mesh="ph_pan_head_screw_m2x0_40_x_10__2803432263e518bbd16bccbbef8784ed" material="ph_pan_head_screw_m2x0_40_x_10__2803432263e518bbd16bccbbef8784ed_material"/>
        <!-- Part side_arm -->
        <geom type="mesh" class="visual" pos="3.46945e-18 -1.38778e-17 0.01815" quat="0.707107 0.707107 0 -5.22714e-17" mesh="side_arm" material="side_arm_material"/>
        <!-- Link ball_link -->
        <body name="ball_link" pos="0.006 -1.38778e-17 -0.0038" quat="7.18919e-15 0.707107 -0.707107 -6.38513e-15">
          <!-- Joint from side_arm to ball_link -->
          <joint axis="0 0 1" name="passive_ball4 (1)" type="ball"/>
          <inertial pos="0.01634 0.00217316 0.000729113" mass="0.000463323" fullinertia="2.80146e-09 6.29293e-08 6.38902e-08 -8.14079e-09 -2.7313e-09 -3.63298e-10"/>
          <!-- Part rotule_lever -->
          <geom type="mesh" class="visual" pos="0.03268 0.00434633 0.00145823" quat="0.596499 0.424332 0.458304 -0.504073" mesh="rotule_lever" material="rotule_lever_material"/>
          <!-- Part rotule_lever_2 -->
          <geom type="mesh" class="visual" pos="-8.74301e-16 -1.17961e-16 -3.84892e-17" quat="0.0563855 0.745858 -0.656481 0.0977179" mesh="rotule_lever" material="rotule_lever_material"/>
          <!-- Part m2_rod_l18 -->
          <geom type="mesh" class="visual" pos="0.0329276 0.00437926 0.00146927" quat="0.0977179 0.656481 0.745858 -0.0563855" mesh="m2_rod_l18" material="m2_rod_l18_material"/>
          <!-- Part spacer -->
          <geom type="mesh" class="visual" pos="0.03268 0.00434633 0.00145823" quat="0.0977179 0.656481 0.745858 -0.0563855" mesh="spacer" material="spacer_material"/>
          <!-- Link rotule_ball -->
          <body name="rotule_ball" pos="0.03268 0.00434633 0.00145823" quat="0.358384 -0.361584 -0.607666 -0.609558">
            <!-- Joint from ball_link to rotule_ball -->
            <joint axis="0 0 1" name="passive_ball2 (1)" type="ball"/>
            <inertial pos="-0.00667513 0.0116212 0.00805" mass="0.00277119" fullinertia="7.15945e-07 1.80812e-07 7.72187e-07 2.46259e-07 2.11758e-22 -2.37401e-22"/>
            <!-- Part link -->
            <geom type="mesh" class="visual" pos="-0.0110508 -0.00359574 0.00805" quat="0.707107 1.0775e-17 -0.707107 1.53291e-16" mesh="link" material="link_material"/>
            <!-- Part ph_pan_head_screw_m2x0_40_x_10__2803432263e518bbd16bccbbef8784ed_2 -->
            <geom type="mesh" class="visual" pos="1.38778e-17 1.38778e-17 -0.0045" quat="2.81643e-17 -0.707107 -0.707107 -4.37387e-15" mesh="ph_pan_head_screw_m2x0_40_x_10__2803432263e518bbd16bccbbef8784ed" material="ph_pan_head_screw_m2x0_40_x_10__2803432263e518bbd16bccbbef8784ed_material"/>
            <!-- Part rotule_ball_2 -->
            <geom type="mesh" class="visual" pos="6.93889e-18 -1.38778e-17 0" quat="1 -0 -0 -4.77217e-18" mesh="rotule_ball" material="rotule_ball_material"/>
            <!-- Part ph_pan_head_screw_m2x0_40_x_10__2803432263e518bbd16bccbbef8784ed_3 -->
            <geom type="mesh" class="visual" pos="-2.08167e-17 -1.38778e-17 0.0206" quat="0.707107 7.7301e-16 -4.05231e-15 0.707107" mesh="ph_pan_head_screw_m2x0_40_x_10__2803432263e518bbd16bccbbef8784ed" material="ph_pan_head_screw_m2x0_40_x_10__2803432263e518bbd16bccbbef8784ed_material"/>
            <!-- Part rotule_ball_3 -->
            <geom type="mesh" class="visual" pos="6.93889e-18 -1.38778e-17 0.0161" quat="1.3311e-15 -1 3.34218e-15 -7.99389e-16" mesh="rotule_ball" material="rotule_ball_material"/>
            <!-- Frame closing_ball1 (1)_1 -->
            <site group="3" name="closing_ball1 (1)_1" pos="6.93889e-18 -1.38778e-17 0.0161" quat="1.3311e-15 -1 3.34218e-15 -7.99389e-16"/>
            <!-- Link std00333_plast_tcb_torx_2_5x8__configuration_copy_of_default -->
            <body name="std00333_plast_tcb_torx_2_5x8__configuration_copy_of_default" pos="-0.00505081 -0.00359574 0.00995" quat="9.08331e-18 -0.707107 -0.707107 -2.46972e-18">
              <!-- Joint from rotule_ball to std00333_plast_tcb_torx_2_5x8__configuration_copy_of_default -->
              <joint axis="0 0 1" name="passive2 (1)" type="hinge"/>
              <inertial pos="-0.0049016 -0.00891862 0.00225" mass="0.00201325" fullinertia="9.75475e-08 4.28021e-08 1.16807e-07 -4.31086e-08 1.21583e-21 2.93812e-21"/>
              <!-- Part std00333_plast_tcb_torx_2_5x8__configuration_copy_of_default -->
              <geom type="mesh" class="visual" pos="-0.0104517 -0.0190172 0.00225" quat="0.608614 -0.359985 0.608614 0.359985" mesh="std00333_plast_tcb_torx_2_5x8__configuration_copy_of_default" material="std00333_plast_tcb_torx_2_5x8__configuration_copy_of_default_material"/>
              <!-- Part gimbal -->
              <geom type="mesh" class="visual" pos="-0.00288986 -0.0052582 0.00225" quat="0.359985 0.608614 0.359985 -0.608614" mesh="gimbal" material="gimbal_material"/>
              <!-- Part plain_washer_large_grade_a_m2_5__9a369f0dc77bf9c598cdf3fb468977e5 -->
              <geom type="mesh" class="visual" pos="-0.00953654 -0.0173521 0.00225" quat="0.359985 0.608614 0.359985 -0.608614" mesh="plain_washer_large_grade_a_m2_5__9a369f0dc77bf9c598cdf3fb468977e5" material="plain_washer_large_grade_a_m2_5__9a369f0dc77bf9c598cdf3fb468977e5_material"/>
              <!-- Part parallel_pin_2_x_10__fee063fca0c8b40e46bbc4ffff61d999 -->
              <geom type="mesh" class="visual" pos="3.05311e-16 -8.32667e-17 0.00225" quat="0.86071 1.64855e-14 3.9635e-14 0.509095" mesh="parallel_pin_2_x_10__fee063fca0c8b40e46bbc4ffff61d999" material="parallel_pin_2_x_10__fee063fca0c8b40e46bbc4ffff61d999_material"/>
              <!-- Frame closing_1 (1)_1 -->
              <site group="3" name="closing_1 (1)_1" pos="-0.00457561 -0.00832549 0.00225" quat="0.359985 0.608614 0.359985 -0.608614"/>
              <!-- Frame closing_1 (1)_1_z -->
              <site group="3" name="closing_1 (1)_1_z" pos="-0.05274 -0.0959622 0.00225" quat="0.359985 0.608614 0.359985 -0.608614"/>
              <!-- Frame closing_3 (1)_2 -->
              <site group="3" name="closing_3 (1)_2" pos="-0.00288986 -0.0052582 -0.00275" quat="0.968599 -1.622e-14 3.91909e-14 -0.248629"/>
              <!-- Frame closing_3 (1)_2_z -->
              <site group="3" name="closing_3 (1)_2_z" pos="-0.00288986 -0.0052582 0.09725" quat="0.968599 -1.622e-14 3.91909e-14 -0.248629"/>
            </body>
            <!-- Link parallel_pin_2_x_10__fee063fca0c8b40e46bbc4ffff61d999 -->
            <body name="parallel_pin_2_x_10__fee063fca0c8b40e46bbc4ffff61d999" pos="-0.0163658 0.0456203 0.00615" quat="0.707107 7.86002e-18 -0 0.707107">
              <!-- Joint from rotule_ball to parallel_pin_2_x_10__fee063fca0c8b40e46bbc4ffff61d999 -->
              <joint axis="0 0 1" name="passive4 (1)" type="hinge"/>
              <inertial pos="0.0150962 -0.0127974 0.00225" mass="0.00540375" fullinertia="3.33567e-07 5.77676e-07 7.69492e-07 3.27688e-07 -5.30211e-22 -1.06193e-21"/>
              <!-- Part std00447_thermoplastique_m2_5x6__configuration_default -->
              <geom type="mesh" class="visual" pos="0.0201331 -0.0157613 -0.00735" quat="0.860105 -6.46823e-15 -3.77476e-15 0.510117" mesh="std00447_thermoplastique_m2_5x6__configuration_default" material="std00447_thermoplastique_m2_5x6__configuration_default_material"/>
              <!-- Part std00447_thermoplastique_m2_5x6__configuration_default_2 -->
              <geom type="mesh" class="visual" pos="0.0201331 -0.0157613 0.01185" quat="6.44092e-15 0.860105 0.510117 3.45056e-15" mesh="std00447_thermoplastique_m2_5x6__configuration_default" material="std00447_thermoplastique_m2_5x6__configuration_default_material"/>
              <!-- Part distal -->
              <geom type="mesh" class="visual" pos="-0.0457364 0.0189381 0.00225" quat="0.360707 -0.608186 -0.360707 -0.608186" mesh="distal" material="distal_material"/>
              <!-- Part distal_shell -->
              <geom type="mesh" class="visual" pos="-0.0457364 0.0189381 0.00225" quat="0.360707 -0.608186 -0.360707 -0.608186" mesh="distal_shell" material="distal_shell_material"/>
              <!-- Part parallel_pin_2_x_10__fee063fca0c8b40e46bbc4ffff61d999_2 -->
              <geom type="mesh" class="visual" pos="2.77556e-17 -1.38778e-17 0.00225" quat="1.49352e-15 0.510117 -0.860105 8.38702e-16" mesh="parallel_pin_2_x_10__fee063fca0c8b40e46bbc4ffff61d999" material="parallel_pin_2_x_10__fee063fca0c8b40e46bbc4ffff61d999_material"/>
              <!-- Frame tip1 -->
              <site group="3" name="tip1" pos="0.0283456 -0.0266027 0.00225" quat="0.68137 0.68137 -0.189036 -0.189036"/>
              <!-- Link parallel_pin_2_x_16__da4b7ddbe9d803fe3fbc70f2e822b99b -->
              <body name="parallel_pin_2_x_16__da4b7ddbe9d803fe3fbc70f2e822b99b" pos="-0.000105947 -0.00599906 0.00655" quat="1.50311e-17 -1 -0.000555496 5.62254e-18">
                <!-- Joint from parallel_pin_2_x_10__fee063fca0c8b40e46bbc4ffff61d999 to parallel_pin_2_x_16__da4b7ddbe9d803fe3fbc70f2e822b99b -->
                <joint axis="0 0 1" name="passive_5 (1)" type="hinge"/>
                <inertial pos="-0.0249171 -0.00392936 0.0052354" mass="0.0101851" fullinertia="4.96149e-07 2.52849e-06 2.3577e-06 2.45138e-08 1.19032e-10 3.03943e-10"/>
                <!-- Part std00447_thermoplastique_m2_5x6__configuration_default_3 -->
                <geom type="mesh" class="visual" pos="-0.022 -0.004 -0.00655" quat="0.707107 4.89923e-16 -3.33067e-16 -0.707107" mesh="std00447_thermoplastique_m2_5x6__configuration_default" material="std00447_thermoplastique_m2_5x6__configuration_default_material"/>
                <!-- Part std00447_thermoplastique_m2_5x6__configuration_default_4 -->
                <geom type="mesh" class="visual" pos="-0.022 -0.004 0.01685" quat="7.35438e-16 -0.707107 0.707107 -7.42291e-16" mesh="std00447_thermoplastique_m2_5x6__configuration_default" material="std00447_thermoplastique_m2_5x6__configuration_default_material"/>
                <!-- Part parallel_pin_2_x_16__da4b7ddbe9d803fe3fbc70f2e822b99b -->
                <geom type="mesh" class="visual" pos="-0.052 2.08167e-17 0.00515" quat="0.707107 0 5.55112e-17 -0.707107" mesh="parallel_pin_2_x_16__da4b7ddbe9d803fe3fbc70f2e822b99b" material="parallel_pin_2_x_16__da4b7ddbe9d803fe3fbc70f2e822b99b_material"/>
                <!-- Part parallel_pin_2_x_16__da4b7ddbe9d803fe3fbc70f2e822b99b_2 -->
                <geom type="mesh" class="visual" pos="-2.77556e-17 6.93889e-18 0.00515" quat="0.707107 -1.71681e-17 -0 -0.707107" mesh="parallel_pin_2_x_16__da4b7ddbe9d803fe3fbc70f2e822b99b" material="parallel_pin_2_x_16__da4b7ddbe9d803fe3fbc70f2e822b99b_material"/>
                <!-- Part proximal_shell -->
                <geom type="mesh" class="visual" pos="-0.052 1.17961e-16 0.00515" quat="0.5 0.5 0.5 -0.5" mesh="proximal_shell" material="proximal_shell_material"/>
                <!-- Part proximal -->
                <geom type="mesh" class="visual" pos="-0.052 2.08167e-17 0.00525" quat="0.5 0.5 0.5 -0.5" mesh="proximal" material="proximal_material"/>
                <!-- Frame closing_3 (1)_1 -->
                <site group="3" name="closing_3 (1)_1" pos="-0.052 2.08167e-17 0" quat="1 -0 -0 -1.02343e-19"/>
                <!-- Frame closing_3 (1)_1_z -->
                <site group="3" name="closing_3 (1)_1_z" pos="-0.052 2.08167e-17 0.1" quat="1 -0 -0 -1.02343e-19"/>
              </body>
            </body>
          </body>
        </body>
      </body>
      <!-- Link rotule_ball_2 -->
      <body name="rotule_ball_2" pos="-0.0046 0.01695 0.070198" quat="0.5 0.5 -0.5 -0.5">
        <!-- Joint from r_wrist_interface to rotule_ball_2 -->
        <joint axis="0 0 1" name="finger1_motor2" type="hinge" range="-1.3962634015954825 1.396263401595445"/>
        <inertial pos="0.006 -1.56061e-17 -0.00345938" mass="0.000410988" fullinertia="4.63584e-09 4.63584e-09 1e-09 -8.11611e-24 -2.88483e-23 -6.67592e-24"/>
        <!-- Part side_arm_2 -->
        <geom type="mesh" class="visual" pos="0 0 0.01815" quat="0.707107 0.707107 0 -5.22714e-17" mesh="side_arm" material="side_arm_material"/>
        <!-- Part rotule_ball_4 -->
        <geom type="mesh" class="visual" pos="0.006 -1.38778e-17 -0.0038" quat="0.707107 -4.02806e-16 4.996e-16 0.707107" mesh="rotule_ball" material="rotule_ball_material"/>
        <!-- Part ph_pan_head_screw_m2x0_40_x_10__2803432263e518bbd16bccbbef8784ed_4 -->
        <geom type="mesh" class="visual" pos="0.006 -2.77556e-17 -0.0083" quat="1.6405e-15 1.13953e-15 -1 5.71983e-16" mesh="ph_pan_head_screw_m2x0_40_x_10__2803432263e518bbd16bccbbef8784ed" material="ph_pan_head_screw_m2x0_40_x_10__2803432263e518bbd16bccbbef8784ed_material"/>
        <!-- Link ball_link_2 -->
        <body name="ball_link_2" pos="0.006 -1.38778e-17 -0.0038" quat="4.04837e-16 0.707107 0.707107 -4.47635e-16">
          <!-- Joint from rotule_ball_2 to ball_link_2 -->
          <joint axis="0 0 1" name="passive_ball3 (1)" type="ball"/>
          <inertial pos="0.0163823 -0.00182695 0.000729113" mass="0.000463323" fullinertia="2.48396e-09 6.32468e-08 6.38902e-08 6.86158e-09 -2.73838e-09 3.05333e-10"/>
          <!-- Part rotule_lever_3 -->
          <geom type="mesh" class="visual" pos="0.0327647 -0.00365389 0.00145823" quat="0.495854 0.522407 0.445832 -0.531463" mesh="rotule_lever" material="rotule_lever_material"/>
          <!-- Part rotule_lever_4 -->
          <geom type="mesh" class="visual" pos="-4.16334e-17 1.73472e-18 -1.19262e-18" quat="0.00640355 0.665873 -0.745199 0.0353708" mesh="rotule_lever" material="rotule_lever_material"/>
          <!-- Part m2_rod_l18_2 -->
          <geom type="mesh" class="visual" pos="0.0330129 -0.00368157 0.00146927" quat="0.0353708 0.745199 0.665873 -0.00640355" mesh="m2_rod_l18" material="m2_rod_l18_material"/>
          <!-- Part spacer_2 -->
          <geom type="mesh" class="visual" pos="0.0327647 -0.00365389 0.00145823" quat="0.0353708 0.745199 0.665873 -0.00640355" mesh="spacer" material="spacer_material"/>
          <!-- Frame closing_ball1 (1)_2 -->
          <site group="3" name="closing_ball1 (1)_2" pos="0.0327647 -0.00365389 0.00145823" quat="0.0251792 -0.0541465 -0.684649 0.726423"/>
        </body>
      </body>
      <!-- Link rotule_ball_3 -->
      <body name="rotule_ball_3" pos="-0.0046 -0.00208344 0.0645128" quat="0.512917 -0.48674 -0.512917 0.48674">
        <!-- Joint from r_wrist_interface to rotule_ball_3 -->
        <joint axis="0 0 1" name="finger2_motor1" type="hinge" range="-1.3962634015955435 1.3962634015953836"/>
        <inertial pos="0.006 1.7923e-17 -0.00345938" mass="0.000410988" fullinertia="4.63584e-09 4.63584e-09 1e-09 2.52289e-24 -2.70698e-23 3.07645e-23"/>
        <!-- Part rotule_ball_5 -->
        <geom type="mesh" class="visual" pos="0.006 1.38778e-17 -0.0038" quat="0.707107 -3.66842e-16 3.00454e-15 -0.707107" mesh="rotule_ball" material="rotule_ball_material"/>
        <!-- Part ph_pan_head_screw_m2x0_40_x_10__2803432263e518bbd16bccbbef8784ed_5 -->
        <geom type="mesh" class="visual" pos="0.006 5.55112e-17 -0.0083" quat="3.83986e-15 -1 -5.40952e-15 1.46336e-15" mesh="ph_pan_head_screw_m2x0_40_x_10__2803432263e518bbd16bccbbef8784ed" material="ph_pan_head_screw_m2x0_40_x_10__2803432263e518bbd16bccbbef8784ed_material"/>
        <!-- Part side_arm_3 -->
        <geom type="mesh" class="visual" pos="2.60209e-18 0 0.01815" quat="0.707107 0.707107 0 -5.46999e-17" mesh="side_arm" material="side_arm_material"/>
        <!-- Link ball_link_3 -->
        <body name="ball_link_3" pos="0.006 1.38778e-17 -0.0038" quat="3.66842e-16 0.707107 -0.707107 -3.0215e-15">
          <!-- Joint from rotule_ball_3 to ball_link_3 -->
          <joint axis="0 0 1" name="passive_ball4 (2)" type="ball"/>
          <inertial pos="0.01634 0.00217316 0.000729113" mass="0.000463323" fullinertia="2.80146e-09 6.29294e-08 6.38902e-08 -8.1408e-09 -2.73129e-09 -3.63303e-10"/>
          <!-- Part rotule_lever_5 -->
          <geom type="mesh" class="visual" pos="0.03268 0.00434633 0.00145823" quat="0.54074 0.478704 0.522928 -0.452757" mesh="rotule_lever" material="rotule_lever_material"/>
          <!-- Part rotule_lever_6 -->
          <geom type="mesh" class="visual" pos="-1.38778e-17 2.60209e-18 1.51788e-18" quat="0.0183467 -0.752127 0.658642 -0.0125945" mesh="rotule_lever" material="rotule_lever_material"/>
          <!-- Part m2_rod_l18_3 -->
          <geom type="mesh" class="visual" pos="0.0329276 0.00437926 0.00146927" quat="0.0125945 0.658642 0.752127 0.0183467" mesh="m2_rod_l18" material="m2_rod_l18_material"/>
          <!-- Part spacer_3 -->
          <geom type="mesh" class="visual" pos="0.03268 0.00434633 0.00145823" quat="0.0125945 0.658642 0.752127 0.0183467" mesh="spacer" material="spacer_material"/>
          <!-- Link rotule_ball_4 -->
          <body name="rotule_ball_4" pos="0.03268 0.00434633 0.00145823" quat="0.358384 -0.361584 -0.607666 -0.609558">
            <!-- Joint from ball_link_3 to rotule_ball_4 -->
            <joint axis="0 0 1" name="passive_ball2 (2)" type="ball"/>
            <inertial pos="-0.00667513 0.0116212 0.00805" mass="0.00277119" fullinertia="7.15945e-07 1.80812e-07 7.72187e-07 2.46259e-07 1.74659e-21 2.48981e-22"/>
            <!-- Part rotule_ball_6 -->
            <geom type="mesh" class="visual" pos="-4.16334e-17 0 0.0161" quat="8.04907e-15 -1 3.06667e-15 -4.61982e-15" mesh="rotule_ball" material="rotule_ball_material"/>
            <!-- Part ph_pan_head_screw_m2x0_40_x_10__2803432263e518bbd16bccbbef8784ed_6 -->
            <geom type="mesh" class="visual" pos="0 -5.55112e-17 -0.0045" quat="3.65885e-15 0.707107 0.707107 -7.94292e-15" mesh="ph_pan_head_screw_m2x0_40_x_10__2803432263e518bbd16bccbbef8784ed" material="ph_pan_head_screw_m2x0_40_x_10__2803432263e518bbd16bccbbef8784ed_material"/>
            <!-- Part link_2 -->
            <geom type="mesh" class="visual" pos="-0.0110508 -0.00359574 0.00805" quat="0.707107 8.00906e-16 -0.707107 -1.12995e-15" mesh="link" material="link_material"/>
            <!-- Part ph_pan_head_screw_m2x0_40_x_10__2803432263e518bbd16bccbbef8784ed_7 -->
            <geom type="mesh" class="visual" pos="-1.31839e-16 0 0.0206" quat="0.707107 3.0704e-15 -9.85323e-15 0.707107" mesh="ph_pan_head_screw_m2x0_40_x_10__2803432263e518bbd16bccbbef8784ed" material="ph_pan_head_screw_m2x0_40_x_10__2803432263e518bbd16bccbbef8784ed_material"/>
            <!-- Part rotule_ball_7 -->
            <geom type="mesh" class="visual" pos="0 -1.38778e-17 0" quat="1 -0 -0 2.33228e-17" mesh="rotule_ball" material="rotule_ball_material"/>
            <!-- Frame closing_ball1 (2)_1 -->
            <site group="3" name="closing_ball1 (2)_1" pos="-4.16334e-17 0 0.0161" quat="8.04907e-15 -1 3.06667e-15 -4.61982e-15"/>
            <!-- Link std00333_plast_tcb_torx_2_5x8__configuration_copy_of_default_2 -->
            <body name="std00333_plast_tcb_torx_2_5x8__configuration_copy_of_default_2" pos="-0.00505081 -0.00359574 0.00995" quat="1.15385e-15 -0.707107 -0.707107 -7.15392e-16">
              <!-- Joint from rotule_ball_4 to std00333_plast_tcb_torx_2_5x8__configuration_copy_of_default_2 -->
              <joint axis="0 0 1" name="passive2 (2)" type="hinge"/>
              <inertial pos="-0.0049016 -0.00891862 0.00225" mass="0.00201325" fullinertia="9.75475e-08 4.28021e-08 1.16807e-07 -4.31086e-08 -1.36046e-21 4.01645e-22"/>
              <!-- Part parallel_pin_2_x_10__fee063fca0c8b40e46bbc4ffff61d999_3 -->
              <geom type="mesh" class="visual" pos="1.38778e-17 0 0.00225" quat="0.86071 5.5535e-15 3.71925e-15 0.509095" mesh="parallel_pin_2_x_10__fee063fca0c8b40e46bbc4ffff61d999" material="parallel_pin_2_x_10__fee063fca0c8b40e46bbc4ffff61d999_material"/>
              <!-- Part std00333_plast_tcb_torx_2_5x8__configuration_copy_of_default_2 -->
              <geom type="mesh" class="visual" pos="-0.0104517 -0.0190172 0.00225" quat="0.608614 -0.359985 0.608614 0.359985" mesh="std00333_plast_tcb_torx_2_5x8__configuration_copy_of_default" material="std00333_plast_tcb_torx_2_5x8__configuration_copy_of_default_material"/>
              <!-- Part plain_washer_large_grade_a_m2_5__9a369f0dc77bf9c598cdf3fb468977e5_2 -->
              <geom type="mesh" class="visual" pos="-0.00953654 -0.0173521 0.00225" quat="0.359985 0.608614 0.359985 -0.608614" mesh="plain_washer_large_grade_a_m2_5__9a369f0dc77bf9c598cdf3fb468977e5" material="plain_washer_large_grade_a_m2_5__9a369f0dc77bf9c598cdf3fb468977e5_material"/>
              <!-- Part gimbal_2 -->
              <geom type="mesh" class="visual" pos="-0.00288986 -0.0052582 0.00225" quat="0.359985 0.608614 0.359985 -0.608614" mesh="gimbal" material="gimbal_material"/>
              <!-- Frame closing_1 (2)_1 -->
              <site group="3" name="closing_1 (2)_1" pos="-0.00457561 -0.00832549 0.00225" quat="0.359985 0.608614 0.359985 -0.608614"/>
              <!-- Frame closing_1 (2)_1_z -->
              <site group="3" name="closing_1 (2)_1_z" pos="-0.05274 -0.0959622 0.00225" quat="0.359985 0.608614 0.359985 -0.608614"/>
              <!-- Frame closing_3 (2)_2 -->
              <site group="3" name="closing_3 (2)_2" pos="-0.00288986 -0.0052582 -0.00275" quat="0.968599 1.5665e-15 6.82787e-15 -0.248629"/>
              <!-- Frame closing_3 (2)_2_z -->
              <site group="3" name="closing_3 (2)_2_z" pos="-0.00288986 -0.0052582 0.09725" quat="0.968599 1.5665e-15 6.82787e-15 -0.248629"/>
            </body>
            <!-- Link parallel_pin_2_x_10__fee063fca0c8b40e46bbc4ffff61d999_2 -->
            <body name="parallel_pin_2_x_10__fee063fca0c8b40e46bbc4ffff61d999_2" pos="-0.0163658 0.0456203 0.00615" quat="0.707107 1.15385e-15 -6.66134e-16 0.707107">
              <!-- Joint from rotule_ball_4 to parallel_pin_2_x_10__fee063fca0c8b40e46bbc4ffff61d999_2 -->
              <joint axis="0 0 1" name="passive4 (2)" type="hinge"/>
              <inertial pos="0.0150962 -0.0127974 0.00225" mass="0.00540375" fullinertia="3.33567e-07 5.77676e-07 7.69492e-07 3.27688e-07 9.02689e-21 1.33855e-20"/>
              <!-- Part distal_2 -->
              <geom type="mesh" class="visual" pos="-0.0457364 0.0189381 0.00225" quat="0.360707 -0.608186 -0.360707 -0.608186" mesh="distal" material="distal_material"/>
              <!-- Part std00447_thermoplastique_m2_5x6__configuration_default_5 -->
              <geom type="mesh" class="visual" pos="0.0201331 -0.0157613 0.01185" quat="8.93088e-15 0.860105 0.510117 1.35917e-14" mesh="std00447_thermoplastique_m2_5x6__configuration_default" material="std00447_thermoplastique_m2_5x6__configuration_default_material"/>
              <!-- Part distal_shell_2 -->
              <geom type="mesh" class="visual" pos="-0.0457364 0.0189381 0.00225" quat="0.360707 -0.608186 -0.360707 -0.608186" mesh="distal_shell" material="distal_shell_material"/>
              <!-- Part std00447_thermoplastique_m2_5x6__configuration_default_6 -->
              <geom type="mesh" class="visual" pos="0.0201331 -0.0157613 -0.00735" quat="0.860105 -7.66253e-15 -1.14353e-14 0.510117" mesh="std00447_thermoplastique_m2_5x6__configuration_default" material="std00447_thermoplastique_m2_5x6__configuration_default_material"/>
              <!-- Part parallel_pin_2_x_10__fee063fca0c8b40e46bbc4ffff61d999_4 -->
              <geom type="mesh" class="visual" pos="0 0 0.00225" quat="7.09237e-15 -0.510117 0.860105 -2.46306e-15" mesh="parallel_pin_2_x_10__fee063fca0c8b40e46bbc4ffff61d999" material="parallel_pin_2_x_10__fee063fca0c8b40e46bbc4ffff61d999_material"/>
              <!-- Frame tip2 -->
              <site group="3" name="tip2" pos="0.0283456 -0.0266027 0.00225" quat="0.68137 0.68137 -0.189036 -0.189036"/>
              <!-- Link parallel_pin_2_x_16__da4b7ddbe9d803fe3fbc70f2e822b99b_2 -->
              <body name="parallel_pin_2_x_16__da4b7ddbe9d803fe3fbc70f2e822b99b_2" pos="-0.000105947 -0.00599906 0.00655" quat="3.16336e-15 -1 -0.000555496 -6.43603e-15">
                <!-- Joint from parallel_pin_2_x_10__fee063fca0c8b40e46bbc4ffff61d999_2 to parallel_pin_2_x_16__da4b7ddbe9d803fe3fbc70f2e822b99b_2 -->
                <joint axis="0 0 1" name="passive_5 (2)" type="hinge"/>
                <inertial pos="-0.0249171 -0.00392936 0.0052354" mass="0.0101851" fullinertia="4.96149e-07 2.52849e-06 2.3577e-06 2.45138e-08 1.19032e-10 3.03943e-10"/>
                <!-- Part parallel_pin_2_x_16__da4b7ddbe9d803fe3fbc70f2e822b99b_3 -->
                <geom type="mesh" class="visual" pos="0 -2.08167e-17 0.00515" quat="0.707107 -4.72673e-17 2.77556e-17 -0.707107" mesh="parallel_pin_2_x_16__da4b7ddbe9d803fe3fbc70f2e822b99b" material="parallel_pin_2_x_16__da4b7ddbe9d803fe3fbc70f2e822b99b_material"/>
                <!-- Part std00447_thermoplastique_m2_5x6__configuration_default_7 -->
                <geom type="mesh" class="visual" pos="-0.022 -0.004 0.01685" quat="5.13216e-16 -0.707107 0.707107 -3.3945e-16" mesh="std00447_thermoplastique_m2_5x6__configuration_default" material="std00447_thermoplastique_m2_5x6__configuration_default_material"/>
                <!-- Part std00447_thermoplastique_m2_5x6__configuration_default_8 -->
                <geom type="mesh" class="visual" pos="-0.022 -0.004 -0.00655" quat="0.707107 1.25723e-16 -1.11022e-16 -0.707107" mesh="std00447_thermoplastique_m2_5x6__configuration_default" material="std00447_thermoplastique_m2_5x6__configuration_default_material"/>
                <!-- Part proximal_2 -->
                <geom type="mesh" class="visual" pos="-0.052 -6.93889e-18 0.00525" quat="0.5 0.5 0.5 -0.5" mesh="proximal" material="proximal_material"/>
                <!-- Part proximal_shell_2 -->
                <geom type="mesh" class="visual" pos="-0.052 9.02056e-17 0.00515" quat="0.5 0.5 0.5 -0.5" mesh="proximal_shell" material="proximal_shell_material"/>
                <!-- Part parallel_pin_2_x_16__da4b7ddbe9d803fe3fbc70f2e822b99b_4 -->
                <geom type="mesh" class="visual" pos="-0.052 -6.93889e-18 0.00515" quat="0.707107 7.70966e-18 -2.81025e-16 -0.707107" mesh="parallel_pin_2_x_16__da4b7ddbe9d803fe3fbc70f2e822b99b" material="parallel_pin_2_x_16__da4b7ddbe9d803fe3fbc70f2e822b99b_material"/>
                <!-- Frame closing_3 (2)_1 -->
                <site group="3" name="closing_3 (2)_1" pos="-0.052 -6.93889e-18 0" quat="1 1.17496e-18 -0 7.79242e-17"/>
                <!-- Frame closing_3 (2)_1_z -->
                <site group="3" name="closing_3 (2)_1_z" pos="-0.052 -6.93889e-18 0.1" quat="1 1.17496e-18 -0 7.79242e-17"/>
              </body>
            </body>
          </body>
        </body>
      </body>
      <!-- Link rotule_ball_5 -->
      <body name="rotule_ball_5" pos="-0.0046 -0.0141669 0.0638795" quat="0.48674 0.512917 -0.48674 -0.512917">
        <!-- Joint from r_wrist_interface to rotule_ball_5 -->
        <joint axis="0 0 1" name="finger2_motor2" type="hinge" range="-1.3962634015954847 1.3962634015954427"/>
        <inertial pos="0.006 1.28889e-17 -0.00345938" mass="0.000410988" fullinertia="4.63584e-09 4.63584e-09 1e-09 -7.62942e-24 -1.54168e-22 -7.64671e-24"/>
        <!-- Part side_arm_4 -->
        <geom type="mesh" class="visual" pos="3.46945e-18 0 0.01815" quat="0.707107 0.707107 0 -5.32949e-17" mesh="side_arm" material="side_arm_material"/>
        <!-- Part ph_pan_head_screw_m2x0_40_x_10__2803432263e518bbd16bccbbef8784ed_8 -->
        <geom type="mesh" class="visual" pos="0.006 2.77556e-17 -0.0083" quat="8.48836e-15 3.6899e-15 -1 -4.76121e-16" mesh="ph_pan_head_screw_m2x0_40_x_10__2803432263e518bbd16bccbbef8784ed" material="ph_pan_head_screw_m2x0_40_x_10__2803432263e518bbd16bccbbef8784ed_material"/>
        <!-- Part rotule_ball_8 -->
        <geom type="mesh" class="visual" pos="0.006 1.38778e-17 -0.0038" quat="0.707107 4.63565e-15 3.66374e-15 0.707107" mesh="rotule_ball" material="rotule_ball_material"/>
        <!-- Link ball_link_4 -->
        <body name="ball_link_4" pos="0.006 1.38778e-17 -0.0038" quat="4.48077e-15 -0.707107 -0.707107 3.69985e-15">
          <!-- Joint from rotule_ball_5 to ball_link_4 -->
          <joint axis="0 0 1" name="passive_ball3 (2)" type="ball"/>
          <inertial pos="0.0163823 -0.00182695 0.000729113" mass="0.000463323" fullinertia="2.48396e-09 6.32469e-08 6.38902e-08 6.86158e-09 -2.73838e-09 3.05332e-10"/>
          <!-- Part rotule_lever_7 -->
          <geom type="mesh" class="visual" pos="0.0327647 -0.00365389 0.00145823" quat="0.477746 0.543114 0.465185 -0.510283" mesh="rotule_lever" material="rotule_lever_material"/>
          <!-- Part rotule_lever_8 -->
          <geom type="mesh" class="visual" pos="1.38778e-17 3.46945e-18 6.50521e-19" quat="0.0232147 -0.666753 0.744864 -0.00888202" mesh="rotule_lever" material="rotule_lever_material"/>
          <!-- Part m2_rod_l18_4 -->
          <geom type="mesh" class="visual" pos="0.0330129 -0.00368157 0.00146927" quat="0.00888202 0.744864 0.666753 0.0232147" mesh="m2_rod_l18" material="m2_rod_l18_material"/>
          <!-- Part spacer_4 -->
          <geom type="mesh" class="visual" pos="0.0327647 -0.00365389 0.00145823" quat="0.00888202 0.744864 0.666753 0.0232147" mesh="spacer" material="spacer_material"/>
          <!-- Frame closing_ball1 (2)_2 -->
          <site group="3" name="closing_ball1 (2)_2" pos="0.0327647 -0.00365389 0.00145823" quat="0.0230076 -0.0551043 -0.712975 0.698642"/>
        </body>
      </body>
      <!-- Link rotule_ball_6 -->
      <body name="rotule_ball_6" pos="-0.0046 -0.032095 0.0541156" quat="0.529551 -0.468589 -0.529551 0.468589">
        <!-- Joint from r_wrist_interface to rotule_ball_6 -->
        <joint axis="0 0 1" name="finger3_motor1" type="hinge" range="-1.3964359085255709 1.3960908946653563"/>
        <inertial pos="0.006 -4.51456e-18 -0.00345938" mass="0.000410988" fullinertia="4.63584e-09 4.63584e-09 1e-09 -1.68544e-23 -2.10981e-23 1.38726e-24"/>
        <!-- Part rotule_ball_9 -->
        <geom type="mesh" class="visual" pos="0.006 6.93889e-18 -0.0038" quat="0.707107 -1.07725e-15 5.82867e-16 -0.707107" mesh="rotule_ball" material="rotule_ball_material"/>
        <!-- Part side_arm_5 -->
        <geom type="mesh" class="visual" pos="1.04083e-17 0 0.01815" quat="0.707107 0.707107 1.11022e-16 -4.7918e-17" mesh="side_arm" material="side_arm_material"/>
        <!-- Part ph_pan_head_screw_m2x0_40_x_10__2803432263e518bbd16bccbbef8784ed_9 -->
        <geom type="mesh" class="visual" pos="0.006 -1.38778e-17 -0.0083" quat="3.51404e-16 1 -9.37057e-16 -1.17937e-15" mesh="ph_pan_head_screw_m2x0_40_x_10__2803432263e518bbd16bccbbef8784ed" material="ph_pan_head_screw_m2x0_40_x_10__2803432263e518bbd16bccbbef8784ed_material"/>
        <!-- Link ball_link_5 -->
        <body name="ball_link_5" pos="0.006 6.93889e-18 -0.0038" quat="1.07725e-15 0.707107 -0.707107 -5.55262e-16">
          <!-- Joint from rotule_ball_6 to ball_link_5 -->
          <joint axis="0 0 1" name="passive_ball4 (3)" type="ball"/>
          <inertial pos="0.0163396 0.00217627 0.00072954" mass="0.000463323" fullinertia="2.8047e-09 6.29263e-08 6.389e-08 -8.15223e-09 -2.73282e-09 -3.64036e-10"/>
          <!-- Part rotule_lever_9 -->
          <geom type="mesh" class="visual" pos="0.0326791 0.00435255 0.00145908" quat="0.540736 0.478706 0.523022 -0.452651" mesh="rotule_lever" material="rotule_lever_material"/>
          <!-- Part rotule_lever_10 -->
          <geom type="mesh" class="visual" pos="-7.63278e-17 -1.38778e-17 -2.92735e-18" quat="0.0184241 -0.752191 0.658569 -0.0125254" mesh="rotule_lever" material="rotule_lever_material"/>
          <!-- Part m2_rod_l18_5 -->
          <geom type="mesh" class="visual" pos="0.0329267 0.00438552 0.00147013" quat="0.0125254 0.658569 0.752191 0.0184241" mesh="m2_rod_l18" material="m2_rod_l18_material"/>
          <!-- Part spacer_5 -->
          <geom type="mesh" class="visual" pos="0.0326791 0.00435255 0.00145908" quat="0.0125254 0.658569 0.752191 0.0184241" mesh="spacer" material="spacer_material"/>
          <!-- Link rotule_ball_7 -->
          <body name="rotule_ball_7" pos="0.0326791 0.00435255 0.00145908" quat="0.358318 -0.360923 -0.608058 -0.609597">
            <!-- Joint from ball_link_5 to rotule_ball_7 -->
            <joint axis="0 0 1" name="passive_ball2 (3)" type="ball"/>
            <inertial pos="-0.00667513 0.0116212 0.00805" mass="0.00277119" fullinertia="7.15945e-07 1.80812e-07 7.72187e-07 2.46259e-07 2.31611e-23 -2.18376e-22"/>
            <!-- Part rotule_ball_10 -->
            <geom type="mesh" class="visual" pos="-6.93889e-18 0 0.0161" quat="7.79501e-18 1 -2.03474e-17 5.64022e-17" mesh="rotule_ball" material="rotule_ball_material"/>
            <!-- Part rotule_ball_11 -->
            <geom type="mesh" class="visual" pos="0 0 0" quat="1 0 0 3.23975e-16" mesh="rotule_ball" material="rotule_ball_material"/>
            <!-- Part ph_pan_head_screw_m2x0_40_x_10__2803432263e518bbd16bccbbef8784ed_10 -->
            <geom type="mesh" class="visual" pos="-1.38778e-17 0 0.0206" quat="0.707107 -8.14305e-17 -2.22045e-16 0.707107" mesh="ph_pan_head_screw_m2x0_40_x_10__2803432263e518bbd16bccbbef8784ed" material="ph_pan_head_screw_m2x0_40_x_10__2803432263e518bbd16bccbbef8784ed_material"/>
            <!-- Part link_3 -->
            <geom type="mesh" class="visual" pos="-0.0110508 -0.00359574 0.00805" quat="0.707107 -3.69628e-18 -0.707107 -3.9789e-16" mesh="link" material="link_material"/>
            <!-- Part ph_pan_head_screw_m2x0_40_x_10__2803432263e518bbd16bccbbef8784ed_11 -->
            <geom type="mesh" class="visual" pos="1.38778e-17 -2.77556e-17 -0.0045" quat="4.33449e-17 -0.707107 -0.707107 2.51364e-17" mesh="ph_pan_head_screw_m2x0_40_x_10__2803432263e518bbd16bccbbef8784ed" material="ph_pan_head_screw_m2x0_40_x_10__2803432263e518bbd16bccbbef8784ed_material"/>
            <!-- Frame closing_ball1 (3)_1 -->
            <site group="3" name="closing_ball1 (3)_1" pos="-6.93889e-18 0 0.0161" quat="7.79501e-18 1 -2.03474e-17 5.64022e-17"/>
            <!-- Link std00333_plast_tcb_torx_2_5x8__configuration_copy_of_default_3 -->
            <body name="std00333_plast_tcb_torx_2_5x8__configuration_copy_of_default_3" pos="-0.00505081 -0.00359574 0.00995" quat="5.40149e-18 0.707107 0.707107 8.88803e-17">
              <!-- Joint from rotule_ball_7 to std00333_plast_tcb_torx_2_5x8__configuration_copy_of_default_3 -->
              <joint axis="0 0 1" name="passive2 (3)" type="hinge"/>
              <inertial pos="-0.00491225 -0.00891276 0.00225" mass="0.00201325" fullinertia="9.74445e-08 4.29052e-08 1.16807e-07 -4.31738e-08 -1.457e-22 -2.43841e-22"/>
              <!-- Part gimbal_3 -->
              <geom type="mesh" class="visual" pos="-0.00289614 -0.00525475 0.00225" quat="0.359621 0.608829 0.359621 -0.608829" mesh="gimbal" material="gimbal_material"/>
              <!-- Part std00333_plast_tcb_torx_2_5x8__configuration_copy_of_default_3 -->
              <geom type="mesh" class="visual" pos="-0.0104744 -0.0190047 0.00225" quat="0.608829 -0.359621 0.608829 0.359621" mesh="std00333_plast_tcb_torx_2_5x8__configuration_copy_of_default" material="std00333_plast_tcb_torx_2_5x8__configuration_copy_of_default_material"/>
              <!-- Part plain_washer_large_grade_a_m2_5__9a369f0dc77bf9c598cdf3fb468977e5_3 -->
              <geom type="mesh" class="visual" pos="-0.00955726 -0.0173407 0.00225" quat="0.359621 0.608829 0.359621 -0.608829" mesh="plain_washer_large_grade_a_m2_5__9a369f0dc77bf9c598cdf3fb468977e5" material="plain_washer_large_grade_a_m2_5__9a369f0dc77bf9c598cdf3fb468977e5_material"/>
              <!-- Part parallel_pin_2_x_10__fee063fca0c8b40e46bbc4ffff61d999_5 -->
              <geom type="mesh" class="visual" pos="-4.16334e-17 1.38778e-17 0.00225" quat="0.861014 -3.08444e-16 -2.22045e-16 0.508581" mesh="parallel_pin_2_x_10__fee063fca0c8b40e46bbc4ffff61d999" material="parallel_pin_2_x_10__fee063fca0c8b40e46bbc4ffff61d999_material"/>
              <!-- Frame closing_1 (3)_1 -->
              <site group="3" name="closing_1 (3)_1" pos="-0.00458556 -0.00832002 0.00225" quat="0.359621 0.608829 0.359621 -0.608829"/>
              <!-- Frame closing_1 (3)_1_z -->
              <site group="3" name="closing_1 (3)_1_z" pos="-0.0528546 -0.0958991 0.00225" quat="0.359621 0.608829 0.359621 -0.608829"/>
              <!-- Frame closing_3 (3)_2 -->
              <site group="3" name="closing_3 (3)_2" pos="-0.00289614 -0.00525475 -0.00275" quat="0.96845 1.63256e-17 -5.55112e-17 -0.249208"/>
              <!-- Frame closing_3 (3)_2_z -->
              <site group="3" name="closing_3 (3)_2_z" pos="-0.00289614 -0.00525475 0.09725" quat="0.96845 1.63256e-17 -5.55112e-17 -0.249208"/>
            </body>
            <!-- Link parallel_pin_2_x_10__fee063fca0c8b40e46bbc4ffff61d999_3 -->
            <body name="parallel_pin_2_x_10__fee063fca0c8b40e46bbc4ffff61d999_3" pos="-0.0163658 0.0456203 0.00615" quat="0.707107 -0 -1.38778e-16 0.707107">
              <!-- Joint from rotule_ball_7 to parallel_pin_2_x_10__fee063fca0c8b40e46bbc4ffff61d999_3 -->
              <joint axis="0 0 1" name="passive4 (3)" type="hinge"/>
              <inertial pos="0.0150828 -0.0128132 0.00225" mass="0.00540375" fullinertia="3.34253e-07 5.7699e-07 7.69492e-07 3.27943e-07 -4.1483e-22 -8.57648e-22"/>
              <!-- Part std00447_thermoplastique_m2_5x6__configuration_default_9 -->
              <geom type="mesh" class="visual" pos="0.0201166 -0.0157824 -0.00735" quat="0.860372 -2.3767e-15 -1.22125e-15 0.509667" mesh="std00447_thermoplastique_m2_5x6__configuration_default" material="std00447_thermoplastique_m2_5x6__configuration_default_material"/>
              <!-- Part std00447_thermoplastique_m2_5x6__configuration_default_10 -->
              <geom type="mesh" class="visual" pos="0.0201166 -0.0157824 0.01185" quat="2.39438e-15 0.860372 0.509667 1.08444e-15" mesh="std00447_thermoplastique_m2_5x6__configuration_default" material="std00447_thermoplastique_m2_5x6__configuration_default_material"/>
              <!-- Part parallel_pin_2_x_10__fee063fca0c8b40e46bbc4ffff61d999_6 -->
              <geom type="mesh" class="visual" pos="0 -2.77556e-17 0.00225" quat="8.75233e-16 0.509667 -0.860372 4.99704e-16" mesh="parallel_pin_2_x_10__fee063fca0c8b40e46bbc4ffff61d999" material="parallel_pin_2_x_10__fee063fca0c8b40e46bbc4ffff61d999_material"/>
              <!-- Part distal_3 -->
              <geom type="mesh" class="visual" pos="-0.0457165 0.018986 0.00225" quat="0.360389 -0.608375 -0.360389 -0.608375" mesh="distal" material="distal_material"/>
              <!-- Part distal_shell_3 -->
              <geom type="mesh" class="visual" pos="-0.0457165 0.018986 0.00225" quat="0.360389 -0.608375 -0.360389 -0.608375" mesh="distal_shell" material="distal_shell_material"/>
              <!-- Frame tip3 -->
              <site group="3" name="tip3" pos="0.0283177 -0.0266324 0.00225" quat="0.681271 0.681271 -0.189393 -0.189393"/>
              <!-- Link parallel_pin_2_x_16__da4b7ddbe9d803fe3fbc70f2e822b99b_3 -->
              <body name="parallel_pin_2_x_16__da4b7ddbe9d803fe3fbc70f2e822b99b_3" pos="-0.00011223 -0.00599895 0.00655" quat="5.40428e-17 1 0.000589821 -1.15232e-16">
                <!-- Joint from parallel_pin_2_x_10__fee063fca0c8b40e46bbc4ffff61d999_3 to parallel_pin_2_x_16__da4b7ddbe9d803fe3fbc70f2e822b99b_3 -->
                <joint axis="0 0 1" name="passive_5 (3)" type="hinge"/>
                <inertial pos="-0.0249171 -0.00392936 0.0052354" mass="0.0101851" fullinertia="4.96149e-07 2.52849e-06 2.3577e-06 2.45138e-08 1.19032e-10 3.03943e-10"/>
                <!-- Part proximal_shell_3 -->
                <geom type="mesh" class="visual" pos="-0.052 1.11022e-16 0.00515" quat="0.5 0.5 0.5 -0.5" mesh="proximal_shell" material="proximal_shell_material"/>
                <!-- Part std00447_thermoplastique_m2_5x6__configuration_default_11 -->
                <geom type="mesh" class="visual" pos="-0.022 -0.004 -0.00655" quat="0.707107 -2.08192e-16 1.66533e-16 -0.707107" mesh="std00447_thermoplastique_m2_5x6__configuration_default" material="std00447_thermoplastique_m2_5x6__configuration_default_material"/>
                <!-- Part proximal_3 -->
                <geom type="mesh" class="visual" pos="-0.052 0 0.00525" quat="0.5 0.5 0.5 -0.5" mesh="proximal" material="proximal_material"/>
                <!-- Part parallel_pin_2_x_16__da4b7ddbe9d803fe3fbc70f2e822b99b_5 -->
                <geom type="mesh" class="visual" pos="-0.052 0 0.00515" quat="0.707107 9.50255e-17 -4.16334e-16 -0.707107" mesh="parallel_pin_2_x_16__da4b7ddbe9d803fe3fbc70f2e822b99b" material="parallel_pin_2_x_16__da4b7ddbe9d803fe3fbc70f2e822b99b_material"/>
                <!-- Part std00447_thermoplastique_m2_5x6__configuration_default_12 -->
                <geom type="mesh" class="visual" pos="-0.022 -0.004 0.01685" quat="6.6042e-17 -0.707107 0.707107 -5.35156e-17" mesh="std00447_thermoplastique_m2_5x6__configuration_default" material="std00447_thermoplastique_m2_5x6__configuration_default_material"/>
                <!-- Part parallel_pin_2_x_16__da4b7ddbe9d803fe3fbc70f2e822b99b_6 -->
                <geom type="mesh" class="visual" pos="0 -1.38778e-17 0.00515" quat="0.707107 -4.06115e-17 1.66533e-16 -0.707107" mesh="parallel_pin_2_x_16__da4b7ddbe9d803fe3fbc70f2e822b99b" material="parallel_pin_2_x_16__da4b7ddbe9d803fe3fbc70f2e822b99b_material"/>
                <!-- Frame closing_3 (3)_1 -->
                <site group="3" name="closing_3 (3)_1" pos="-0.052 0 -6.93889e-18" quat="1 0 1.66533e-16 8.88655e-17"/>
                <!-- Frame closing_3 (3)_1_z -->
                <site group="3" name="closing_3 (3)_1_z" pos="-0.052 0 0.1" quat="1 0 1.66533e-16 8.88655e-17"/>
              </body>
            </body>
          </body>
        </body>
      </body>
      <!-- Link side_arm_2 -->
      <body name="side_arm_2" pos="-0.0046 -0.0441048 0.052641" quat="0.467918 0.530144 -0.467918 -0.530144">
        <!-- Joint from r_wrist_interface to side_arm_2 -->
        <joint axis="0 0 1" name="finger3_motor2" type="hinge" range="-1.393904103250541 1.3986226999403863"/>
        <inertial pos="0.006 -5.10332e-18 -0.00345938" mass="0.000410988" fullinertia="4.63584e-09 4.63584e-09 1e-09 1.02955e-23 -3.94269e-23 -3.66815e-25"/>
        <!-- Part side_arm_6 -->
        <geom type="mesh" class="visual" pos="6.93889e-18 0 0.01815" quat="0.707107 0.707107 -0 -5.1415e-17" mesh="side_arm" material="side_arm_material"/>
        <!-- Part rotule_ball_12 -->
        <geom type="mesh" class="visual" pos="0.006 0 -0.0038" quat="0.707107 1.01755e-15 5.55112e-16 0.707107" mesh="rotule_ball" material="rotule_ball_material"/>
        <!-- Part ph_pan_head_screw_m2x0_40_x_10__2803432263e518bbd16bccbbef8784ed_12 -->
        <geom type="mesh" class="visual" pos="0.006 -6.93889e-18 -0.0083" quat="2.06117e-15 1.96571e-15 -1 4.34502e-16" mesh="ph_pan_head_screw_m2x0_40_x_10__2803432263e518bbd16bccbbef8784ed" material="ph_pan_head_screw_m2x0_40_x_10__2803432263e518bbd16bccbbef8784ed_material"/>
        <!-- Link ball_link_6 -->
        <body name="ball_link_6" pos="0.006 0 -0.0038" quat="1.01006e-15 -0.707107 -0.707107 9.28853e-16">
          <!-- Joint from side_arm_2 to ball_link_6 -->
          <joint axis="0 0 1" name="passive_ball3 (3)" type="ball"/>
          <inertial pos="0.016378 -0.00186526 0.00072954" mass="0.000463323" fullinertia="2.51653e-09 6.32144e-08 6.389e-08 7.00362e-09 -2.73926e-09 3.1192e-10"/>
          <!-- Part rotule_lever_11 -->
          <geom type="mesh" class="visual" pos="0.032756 -0.00373052 0.00145908" quat="0.477164 0.543654 0.464534 -0.510845" mesh="rotule_lever" material="rotule_lever_material"/>
          <!-- Part rotule_lever_12 -->
          <geom type="mesh" class="visual" pos="-2.08167e-17 0 -1.0842e-19" quat="0.0231996 -0.665881 0.745644 -0.00893073" mesh="rotule_lever" material="rotule_lever_material"/>
          <!-- Part m2_rod_l18_6 -->
          <geom type="mesh" class="visual" pos="0.0330041 -0.00375879 0.00147013" quat="0.00893073 0.745644 0.665881 0.0231996" mesh="m2_rod_l18" material="m2_rod_l18_material"/>
          <!-- Part spacer_6 -->
          <geom type="mesh" class="visual" pos="0.032756 -0.00373052 0.00145908" quat="0.00893073 0.745644 0.665881 0.0231996" mesh="spacer" material="spacer_material"/>
          <!-- Frame closing_ball1 (3)_2 -->
          <site group="3" name="closing_ball1 (3)_2" pos="0.032756 -0.00373052 0.00145908" quat="0.0238165 -0.0559467 -0.712897 0.698628"/>
        </body>
      </body>
      <!-- Link side_arm_3 -->
      <body name="side_arm_3" pos="7.5027e-05 0.00636953 0.0366" quat="5.63481e-15 -0.819152 0.573576 5.85635e-15">
        <!-- Joint from r_wrist_interface to side_arm_3 -->
        <joint axis="0 0 1" name="finger4_motor1" type="hinge" range="-1.3962634015954316 1.3962634015954956"/>
        <inertial pos="0.006 4.37024e-18 -0.00345938" mass="0.000410988" fullinertia="4.63584e-09 4.63584e-09 1e-09 -5.14553e-24 -1.47465e-22 -1.02002e-24"/>
        <!-- Part rotule_ball_13 -->
        <geom type="mesh" class="visual" pos="0.006 5.20417e-18 -0.0038" quat="0.707107 -5.24396e-15 6.10623e-15 -0.707107" mesh="rotule_ball" material="rotule_ball_material"/>
        <!-- Part side_arm_7 -->
        <geom type="mesh" class="visual" pos="2.60209e-18 0 0.01815" quat="0.707107 0.707107 1.11022e-16 4.80911e-17" mesh="side_arm" material="side_arm_material"/>
        <!-- Part ph_pan_head_screw_m2x0_40_x_10__2803432263e518bbd16bccbbef8784ed_13 -->
        <geom type="mesh" class="visual" pos="0.006 1.38778e-17 -0.0083" quat="4.91767e-16 -1 2.58905e-16 8.00566e-15" mesh="ph_pan_head_screw_m2x0_40_x_10__2803432263e518bbd16bccbbef8784ed" material="ph_pan_head_screw_m2x0_40_x_10__2803432263e518bbd16bccbbef8784ed_material"/>
        <!-- Link ball_link_7 -->
        <body name="ball_link_7" pos="0.006 5.20417e-18 -0.0038" quat="5.3128e-15 0.707107 -0.707107 -6.00891e-15">
          <!-- Joint from side_arm_3 to ball_link_7 -->
          <joint axis="0 0 1" name="passive_ball4 (4)" type="ball"/>
          <inertial pos="0.01634 0.00217316 0.000729113" mass="0.000463323" fullinertia="2.80146e-09 6.29293e-08 6.38902e-08 -8.14079e-09 -2.7313e-09 -3.63284e-10"/>
          <!-- Part rotule_lever_13 -->
          <geom type="mesh" class="visual" pos="8.67362e-19 -3.32037e-19 1.38778e-17" quat="0.645291 -0.184773 0.133214 0.729186" mesh="rotule_lever" material="rotule_lever_material"/>
          <!-- Part rotule_lever_14 -->
          <geom type="mesh" class="visual" pos="0.03268 0.00434633 0.00145823" quat="0.384958 -0.550486 -0.646267 -0.362093" mesh="rotule_lever" material="rotule_lever_material"/>
          <!-- Part m2_rod_l18_7 -->
          <geom type="mesh" class="visual" pos="-0.000247576 -3.29267e-05 -1.10472e-05" quat="0.362093 -0.646267 0.550486 0.384958" mesh="m2_rod_l18" material="m2_rod_l18_material"/>
          <!-- Part spacer_7 -->
          <geom type="mesh" class="visual" pos="2.16407e-16 2.11135e-16 3.95517e-16" quat="0.362093 -0.646267 0.550486 0.384958" mesh="spacer" material="spacer_material"/>
          <!-- Link rotule_ball_8 -->
          <body name="rotule_ball_8" pos="0.03268 0.00434633 0.00145823" quat="0.358384 -0.361584 -0.607666 -0.609558">
            <!-- Joint from ball_link_7 to rotule_ball_8 -->
            <joint axis="0 0 1" name="passive_ball2 (4)" type="ball"/>
            <inertial pos="-0.00667513 0.0116212 0.00805" mass="0.00277119" fullinertia="7.15945e-07 1.80812e-07 7.72187e-07 2.46259e-07 4.2972e-22 -2.77106e-22"/>
            <!-- Part rotule_ball_14 -->
            <geom type="mesh" class="visual" pos="0 6.93889e-18 8.67362e-19" quat="1 0 -1.11022e-16 1.20992e-17" mesh="rotule_ball" material="rotule_ball_material"/>
            <!-- Part link_4 -->
            <geom type="mesh" class="visual" pos="-0.0110508 -0.00359574 0.00805" quat="0.707107 -2.88171e-17 -0.707107 -3.1044e-16" mesh="link" material="link_material"/>
            <!-- Part ph_pan_head_screw_m2x0_40_x_10__2803432263e518bbd16bccbbef8784ed_14 -->
            <geom type="mesh" class="visual" pos="-1.38778e-17 -6.93889e-18 0.0206" quat="0.707107 -4.83405e-15 -1.22125e-15 0.707107" mesh="ph_pan_head_screw_m2x0_40_x_10__2803432263e518bbd16bccbbef8784ed" material="ph_pan_head_screw_m2x0_40_x_10__2803432263e518bbd16bccbbef8784ed_material"/>
            <!-- Part ph_pan_head_screw_m2x0_40_x_10__2803432263e518bbd16bccbbef8784ed_15 -->
            <geom type="mesh" class="visual" pos="0 2.08167e-17 -0.0045" quat="2.14403e-15 0.707107 0.707107 6.20641e-15" mesh="ph_pan_head_screw_m2x0_40_x_10__2803432263e518bbd16bccbbef8784ed" material="ph_pan_head_screw_m2x0_40_x_10__2803432263e518bbd16bccbbef8784ed_material"/>
            <!-- Part rotule_ball_15 -->
            <geom type="mesh" class="visual" pos="-1.04083e-17 0 0.0161" quat="2.56608e-15 1 7.96034e-15 4.8054e-15" mesh="rotule_ball" material="rotule_ball_material"/>
            <!-- Frame closing_ball1 (4)_1 -->
            <site group="3" name="closing_ball1 (4)_1" pos="-1.04083e-17 0 0.0161" quat="2.56608e-15 1 7.96034e-15 4.8054e-15"/>
            <!-- Link std00333_plast_tcb_torx_2_5x8__configuration_copy_of_default_4 -->
            <body name="std00333_plast_tcb_torx_2_5x8__configuration_copy_of_default_4" pos="-0.00505081 -0.00359574 0.00995" quat="3.96708e-18 -0.707107 -0.707107 -6.89581e-17">
              <!-- Joint from rotule_ball_8 to std00333_plast_tcb_torx_2_5x8__configuration_copy_of_default_4 -->
              <joint axis="0 0 1" name="passive2 (4)" type="hinge"/>
              <inertial pos="-0.0049016 -0.00891862 0.00225" mass="0.00201325" fullinertia="9.75475e-08 4.28021e-08 1.16807e-07 -4.31086e-08 -1.68571e-22 -2.91211e-22"/>
              <!-- Part parallel_pin_2_x_10__fee063fca0c8b40e46bbc4ffff61d999_7 -->
              <geom type="mesh" class="visual" pos="6.93889e-18 -1.04083e-17 0.00225" quat="0.86071 1.65432e-16 -1.11022e-16 0.509095" mesh="parallel_pin_2_x_10__fee063fca0c8b40e46bbc4ffff61d999" material="parallel_pin_2_x_10__fee063fca0c8b40e46bbc4ffff61d999_material"/>
              <!-- Part plain_washer_large_grade_a_m2_5__9a369f0dc77bf9c598cdf3fb468977e5_4 -->
              <geom type="mesh" class="visual" pos="-0.00953654 -0.0173521 0.00225" quat="0.359985 0.608614 0.359985 -0.608614" mesh="plain_washer_large_grade_a_m2_5__9a369f0dc77bf9c598cdf3fb468977e5" material="plain_washer_large_grade_a_m2_5__9a369f0dc77bf9c598cdf3fb468977e5_material"/>
              <!-- Part gimbal_4 -->
              <geom type="mesh" class="visual" pos="-0.00288986 -0.0052582 0.00225" quat="0.359985 0.608614 0.359985 -0.608614" mesh="gimbal" material="gimbal_material"/>
              <!-- Part std00333_plast_tcb_torx_2_5x8__configuration_copy_of_default_4 -->
              <geom type="mesh" class="visual" pos="-0.0104517 -0.0190172 0.00225" quat="0.608614 -0.359985 0.608614 0.359985" mesh="std00333_plast_tcb_torx_2_5x8__configuration_copy_of_default" material="std00333_plast_tcb_torx_2_5x8__configuration_copy_of_default_material"/>
              <!-- Frame closing_1 (4)_1 -->
              <site group="3" name="closing_1 (4)_1" pos="-0.00457561 -0.00832549 0.00225" quat="0.359985 0.608614 0.359985 -0.608614"/>
              <!-- Frame closing_1 (4)_1_z -->
              <site group="3" name="closing_1 (4)_1_z" pos="-0.05274 -0.0959622 0.00225" quat="0.359985 0.608614 0.359985 -0.608614"/>
              <!-- Frame closing_3 (4)_2 -->
              <site group="3" name="closing_3 (4)_2" pos="-0.00288986 -0.0052582 -0.00275" quat="0.968599 7.60209e-18 -5.55112e-17 -0.248629"/>
              <!-- Frame closing_3 (4)_2_z -->
              <site group="3" name="closing_3 (4)_2_z" pos="-0.00288986 -0.0052582 0.09725" quat="0.968599 7.60209e-18 -5.55112e-17 -0.248629"/>
            </body>
            <!-- Link parallel_pin_2_x_10__fee063fca0c8b40e46bbc4ffff61d999_4 -->
            <body name="parallel_pin_2_x_10__fee063fca0c8b40e46bbc4ffff61d999_4" pos="-0.0163658 0.0456203 0.00615" quat="0.707107 -0 -1.31839e-16 0.707107">
              <!-- Joint from rotule_ball_8 to parallel_pin_2_x_10__fee063fca0c8b40e46bbc4ffff61d999_4 -->
              <joint axis="0 0 1" name="passive4 (4)" type="hinge"/>
              <inertial pos="0.0150962 -0.0127974 0.00225" mass="0.00540375" fullinertia="3.33567e-07 5.77676e-07 7.69492e-07 3.27688e-07 -2.74459e-21 -4.98128e-21"/>
              <!-- Part distal_shell_4 -->
              <geom type="mesh" class="visual" pos="-0.0457364 0.0189381 0.00225" quat="0.360707 -0.608186 -0.360707 -0.608186" mesh="distal_shell" material="distal_shell_material"/>
              <!-- Part std00447_thermoplastique_m2_5x6__configuration_default_13 -->
              <geom type="mesh" class="visual" pos="0.0201331 -0.0157613 0.01185" quat="1.36337e-15 -0.860105 -0.510117 -3.11904e-15" mesh="std00447_thermoplastique_m2_5x6__configuration_default" material="std00447_thermoplastique_m2_5x6__configuration_default_material"/>
              <!-- Part parallel_pin_2_x_10__fee063fca0c8b40e46bbc4ffff61d999_8 -->
              <geom type="mesh" class="visual" pos="-2.77556e-17 -6.93889e-18 0.00225" quat="1.6825e-16 -0.510117 0.860105 8.18573e-17" mesh="parallel_pin_2_x_10__fee063fca0c8b40e46bbc4ffff61d999" material="parallel_pin_2_x_10__fee063fca0c8b40e46bbc4ffff61d999_material"/>
              <!-- Part distal_4 -->
              <geom type="mesh" class="visual" pos="-0.0457364 0.0189381 0.00225" quat="0.360707 -0.608186 -0.360707 -0.608186" mesh="distal" material="distal_material"/>
              <!-- Part std00447_thermoplastique_m2_5x6__configuration_default_14 -->
              <geom type="mesh" class="visual" pos="0.0201331 -0.0157613 -0.00735" quat="0.860105 -1.13178e-14 1.55431e-15 0.510117" mesh="std00447_thermoplastique_m2_5x6__configuration_default" material="std00447_thermoplastique_m2_5x6__configuration_default_material"/>
              <!-- Frame tip4 -->
              <site group="3" name="tip4" pos="0.0283456 -0.0266027 0.00225" quat="0.68137 0.68137 -0.189036 -0.189036"/>
              <!-- Link parallel_pin_2_x_16__da4b7ddbe9d803fe3fbc70f2e822b99b_4 -->
              <body name="parallel_pin_2_x_16__da4b7ddbe9d803fe3fbc70f2e822b99b_4" pos="-0.000105947 -0.00599906 0.00655" quat="1.6408e-15 1 0.000555496 2.29986e-15">
                <!-- Joint from parallel_pin_2_x_10__fee063fca0c8b40e46bbc4ffff61d999_4 to parallel_pin_2_x_16__da4b7ddbe9d803fe3fbc70f2e822b99b_4 -->
                <joint axis="0 0 1" name="passive_5 (4)" type="hinge"/>
                <inertial pos="-0.0249171 -0.00392936 0.0052354" mass="0.0101851" fullinertia="4.96149e-07 2.52849e-06 2.3577e-06 2.45138e-08 1.19032e-10 3.03943e-10"/>
                <!-- Part std00447_thermoplastique_m2_5x6__configuration_default_15 -->
                <geom type="mesh" class="visual" pos="-0.022 -0.004 0.01685" quat="4.23362e-16 0.707107 -0.707107 -1.68469e-15" mesh="std00447_thermoplastique_m2_5x6__configuration_default" material="std00447_thermoplastique_m2_5x6__configuration_default_material"/>
                <!-- Part parallel_pin_2_x_16__da4b7ddbe9d803fe3fbc70f2e822b99b_7 -->
                <geom type="mesh" class="visual" pos="-0.052 1.9082e-17 0.00515" quat="0.707107 1.06418e-15 -1.33227e-15 -0.707107" mesh="parallel_pin_2_x_16__da4b7ddbe9d803fe3fbc70f2e822b99b" material="parallel_pin_2_x_16__da4b7ddbe9d803fe3fbc70f2e822b99b_material"/>
                <!-- Part parallel_pin_2_x_16__da4b7ddbe9d803fe3fbc70f2e822b99b_8 -->
                <geom type="mesh" class="visual" pos="0 -1.73472e-17 0.00515" quat="0.707107 2.29735e-15 -1.22125e-15 -0.707107" mesh="parallel_pin_2_x_16__da4b7ddbe9d803fe3fbc70f2e822b99b" material="parallel_pin_2_x_16__da4b7ddbe9d803fe3fbc70f2e822b99b_material"/>
                <!-- Part proximal_shell_4 -->
                <geom type="mesh" class="visual" pos="-0.052 -6.93889e-18 0.00515" quat="0.5 0.5 0.5 -0.5" mesh="proximal_shell" material="proximal_shell_material"/>
                <!-- Part proximal_4 -->
                <geom type="mesh" class="visual" pos="-0.052 1.38778e-17 0.00525" quat="0.5 0.5 0.5 -0.5" mesh="proximal" material="proximal_material"/>
                <!-- Part std00447_thermoplastique_m2_5x6__configuration_default_16 -->
                <geom type="mesh" class="visual" pos="-0.022 -0.004 -0.00655" quat="0.707107 -1.0151e-15 3.10862e-15 -0.707107" mesh="std00447_thermoplastique_m2_5x6__configuration_default" material="std00447_thermoplastique_m2_5x6__configuration_default_material"/>
                <!-- Frame closing_3 (4)_1 -->
                <site group="3" name="closing_3 (4)_1" pos="-0.052 1.21431e-17 3.46945e-18" quat="1 0 0 1.5157e-16"/>
                <!-- Frame closing_3 (4)_1_z -->
                <site group="3" name="closing_3 (4)_1_z" pos="-0.052 1.38778e-17 0.1" quat="1 0 0 1.5157e-16"/>
              </body>
            </body>
          </body>
        </body>
      </body>
      <!-- Link rotule_ball_9 -->
      <body name="rotule_ball_9" pos="-0.00406342 0.0177398 0.0366" quat="1.97195e-14 -0.573576 -0.819152 -1.4537e-14">
        <!-- Joint from r_wrist_interface to rotule_ball_9 -->
        <joint axis="0 0 1" name="finger4_motor2" type="hinge" range="-1.3962634015953883 1.396263401595539"/>
        <inertial pos="0.006 5.68351e-19 -0.00345938" mass="0.000410988" fullinertia="4.63584e-09 4.63584e-09 1e-09 6.08518e-24 -2.26674e-24 1.63987e-24"/>
        <!-- Part ph_pan_head_screw_m2x0_40_x_10__2803432263e518bbd16bccbbef8784ed_16 -->
        <geom type="mesh" class="visual" pos="0.006 3.03577e-18 -0.0083" quat="7.26802e-17 -5.17679e-16 -1 -2.98428e-16" mesh="ph_pan_head_screw_m2x0_40_x_10__2803432263e518bbd16bccbbef8784ed" material="ph_pan_head_screw_m2x0_40_x_10__2803432263e518bbd16bccbbef8784ed_material"/>
        <!-- Part rotule_ball_16 -->
        <geom type="mesh" class="visual" pos="0.006 4.33681e-19 -0.0038" quat="0.707107 2.65094e-16 -1.11022e-16 0.707107" mesh="rotule_ball" material="rotule_ball_material"/>
        <!-- Part side_arm_8 -->
        <geom type="mesh" class="visual" pos="3.46945e-18 0 0.01815" quat="0.707107 0.707107 0 -5.51309e-17" mesh="side_arm" material="side_arm_material"/>
        <!-- Link ball_link_8 -->
        <body name="ball_link_8" pos="0.006 4.33681e-19 -0.0038" quat="1.93213e-16 -0.707107 -0.707107 1.43836e-17">
          <!-- Joint from rotule_ball_9 to ball_link_8 -->
          <joint axis="0 0 1" name="passive_ball3 (4)" type="ball"/>
          <inertial pos="0.0163823 -0.00182695 0.000729113" mass="0.000463323" fullinertia="2.48396e-09 6.32469e-08 6.38902e-08 6.86158e-09 -2.73838e-09 3.05332e-10"/>
          <!-- Part rotule_lever_15 -->
          <geom type="mesh" class="visual" pos="-4.33681e-19 6.93889e-18 0" quat="0.745107 -0.0177063 -0.0133538 0.666577" mesh="rotule_lever" material="rotule_lever_material"/>
          <!-- Part rotule_lever_16 -->
          <geom type="mesh" class="visual" pos="0.0327647 -0.00365389 0.00145823" quat="0.458821 -0.517427 -0.483861 -0.536312" mesh="rotule_lever" material="rotule_lever_material"/>
          <!-- Part m2_rod_l18_8 -->
          <geom type="mesh" class="visual" pos="-0.000248217 2.7681e-05 -1.10472e-05" quat="0.536312 -0.483861 0.517427 0.458821" mesh="m2_rod_l18" material="m2_rod_l18_material"/>
          <!-- Part spacer_8 -->
          <geom type="mesh" class="visual" pos="2.03396e-16 -1.73472e-17 4.30211e-16" quat="0.536312 -0.483861 0.517427 0.458821" mesh="spacer" material="spacer_material"/>
          <!-- Frame closing_ball1 (4)_2 -->
          <site group="3" name="closing_ball1 (4)_2" pos="0.0327647 -0.00365389 0.00145823" quat="0.0237349 -0.0547949 -0.703665 0.708018"/>
        </body>
      </body>
    </body>
  </worldbody>
  <asset>
    <mesh file="rotule_lever.stl"/>
    <mesh file="parallel_pin_2_x_16__da4b7ddbe9d803fe3fbc70f2e822b99b.stl"/>
    <mesh file="r_wrist_interface.stl"/>
    <mesh file="link.stl"/>
    <mesh file="sts3032.stl"/>
    <mesh file="side_arm.stl"/>
    <mesh file="r_hand_plate.stl"/>
    <mesh file="spacer.stl"/>
    <mesh file="ph_pan_head_screw_m2x0_40_x_10__2803432263e518bbd16bccbbef8784ed.stl"/>
    <mesh file="gimbal.stl"/>
    <mesh file="distal.stl"/>
    <mesh file="m2_rod_l18.stl"/>
    <mesh file="proximal.stl"/>
    <mesh file="bushing_0608_04.stl"/>
    <mesh file="proximal_shell.stl"/>
    <mesh file="std00447_thermoplastique_m2_5x6__configuration_default.stl"/>
    <mesh file="rotule_ball.stl"/>
    <mesh file="distal_shell.stl"/>
    <mesh file="parallel_pin_2_x_10__fee063fca0c8b40e46bbc4ffff61d999.stl"/>
    <mesh file="finger_frame.stl"/>
    <mesh file="std00333_plast_tcb_torx_2_5x8__configuration_copy_of_default.stl"/>
    <mesh file="plain_washer_large_grade_a_m2_5__9a369f0dc77bf9c598cdf3fb468977e5.stl"/>
    <material name="sts3032_material" rgba="0.972549 0.529412 0.00392157 1"/>
    <material name="r_hand_plate_material" rgba="0.301961 0.301961 0.301961 1"/>
    <material name="finger_frame_material" rgba="0.8 0.8 0.8 1"/>
    <material name="bushing_0608_04_material" rgba="0.301961 0.301961 0.301961 1"/>
    <material name="r_wrist_interface_material" rgba="0.301961 0.301961 0.301961 1"/>
    <material name="rotule_ball_material" rgba="0.960784 0.835294 0.470588 1"/>
    <material name="ph_pan_head_screw_m2x0_40_x_10__2803432263e518bbd16bccbbef8784ed_material" rgba="0.603922 0.647059 0.686275 1"/>
    <material name="side_arm_material" rgba="1 1 1 1"/>
    <material name="rotule_lever_material" rgba="0.196078 0.196078 0.196078 1"/>
    <material name="m2_rod_l18_material" rgba="0.811765 0.858824 0.898039 1"/>
    <material name="spacer_material" rgba="0.501961 0.501961 0.501961 1"/>
    <material name="link_material" rgba="0.8 0.8 0.8 1"/>
    <material name="std00333_plast_tcb_torx_2_5x8__configuration_copy_of_default_material" rgba="0.901961 0.901961 0.901961 1"/>
    <material name="gimbal_material" rgba="0.8 0.8 0.8 1"/>
    <material name="plain_washer_large_grade_a_m2_5__9a369f0dc77bf9c598cdf3fb468977e5_material" rgba="0.603922 0.647059 0.686275 1"/>
    <material name="parallel_pin_2_x_10__fee063fca0c8b40e46bbc4ffff61d999_material" rgba="0.603922 0.647059 0.686275 1"/>
    <material name="std00447_thermoplastique_m2_5x6__configuration_default_material" rgba="0.901961 0.901961 0.901961 1"/>
    <material name="distal_material" rgba="0.8 0.8 0.8 1"/>
    <material name="distal_shell_material" rgba="1 1 1 1"/>
    <material name="parallel_pin_2_x_16__da4b7ddbe9d803fe3fbc70f2e822b99b_material" rgba="0.603922 0.647059 0.686275 1"/>
    <material name="proximal_shell_material" rgba="1 1 1 1"/>
    <material name="proximal_material" rgba="0.8 0.8 0.8 1"/>
  </asset>
  <actuator>
    <position class="mjcf" name="finger1_motor1" joint="finger1_motor1" inheritrange="1"/>
    <position class="mjcf" name="finger1_motor2" joint="finger1_motor2" inheritrange="1"/>
    <position class="mjcf" name="finger2_motor1" joint="finger2_motor1" inheritrange="1"/>
    <position class="mjcf" name="finger2_motor2" joint="finger2_motor2" inheritrange="1"/>
    <position class="mjcf" name="finger3_motor1" joint="finger3_motor1" inheritrange="1"/>
    <position class="mjcf" name="finger3_motor2" joint="finger3_motor2" inheritrange="1"/>
    <position class="mjcf" name="finger4_motor1" joint="finger4_motor1" inheritrange="1"/>
    <position class="mjcf" name="finger4_motor2" joint="finger4_motor2" inheritrange="1"/>
  </actuator>
  <equality>
    <connect site1="closing_1 (1)_1" site2="closing_1 (1)_2"/>
    <connect site1="closing_1 (1)_1_z" site2="closing_1 (1)_2_z"/>
    <connect site1="closing_ball1 (1)_1" site2="closing_ball1 (1)_2"/>
    <connect site1="closing_3 (1)_1" site2="closing_3 (1)_2"/>
    <connect site1="closing_3 (1)_1_z" site2="closing_3 (1)_2_z"/>
    <connect site1="closing_1 (2)_1" site2="closing_1 (2)_2"/>
    <connect site1="closing_1 (2)_1_z" site2="closing_1 (2)_2_z"/>
    <connect site1="closing_ball1 (2)_1" site2="closing_ball1 (2)_2"/>
    <connect site1="closing_3 (2)_1" site2="closing_3 (2)_2"/>
    <connect site1="closing_3 (2)_1_z" site2="closing_3 (2)_2_z"/>
    <connect site1="closing_1 (3)_1" site2="closing_1 (3)_2"/>
    <connect site1="closing_1 (3)_1_z" site2="closing_1 (3)_2_z"/>
    <connect site1="closing_ball1 (3)_1" site2="closing_ball1 (3)_2"/>
    <connect site1="closing_3 (3)_1" site2="closing_3 (3)_2"/>
    <connect site1="closing_3 (3)_1_z" site2="closing_3 (3)_2_z"/>
    <connect site1="closing_1 (4)_1" site2="closing_1 (4)_2"/>
    <connect site1="closing_1 (4)_1_z" site2="closing_1 (4)_2_z"/>
    <connect site1="closing_ball1 (4)_1" site2="closing_ball1 (4)_2"/>
    <connect site1="closing_3 (4)_1" site2="closing_3 (4)_2"/>
    <connect site1="closing_3 (4)_1_z" site2="closing_3 (4)_2_z"/>
  </equality>
</mujoco>
